<?xml version="1.0" ?>
<!-- =================================================================================== -->
<!-- |    This document was autogenerated by xacro from /home/dyyt/adog_ws/adog_legged_control/legacy/unitree_go2_description/xacro/robot.xacro | -->
<!-- |    EDITING THIS FILE BY HAND IS NOT RECOMMENDED                                 | -->
<!-- =================================================================================== -->
<robot name="go2">
  <material name="black">
    <color rgba="0.0 0.0 0.0 1.0"/>
  </material>
  <material name="blue">
    <color rgba="0.0 0.0 0.8 1.0"/>
  </material>
  <material name="green">
    <color rgba="0.0 0.8 0.0 1.0"/>
  </material>
  <material name="grey">
    <color rgba="0.2 0.2 0.2 0.0"/>
  </material>
  <material name="silver">
    <color rgba="0.9137254901960784 0.9137254901960784 0.8470588235294118 1.0"/>
  </material>
  <material name="orange">
    <color rgba="1.0 0.4235294117647059 0.0392156862745098 1.0"/>
  </material>
  <material name="brown">
    <color rgba="0.8705882352941177 0.8117647058823529 0.7647058823529411 1.0"/>
  </material>
  <material name="red">
    <color rgba="0.8 0.0 0.0 1.0"/>
  </material>
  <material name="white">
    <color rgba="1.0 1.0 1.0 1.0"/>
  </material>
  <ros2_control name="LegSystemHardware" type="system">
    <hardware>
      <plugin>gazebo_ros2_control/GazeboSystem</plugin>
    </hardware>
    <joint name="FL_hip_joint">
      <command_interface name="effort"/>
      <command_interface name="velocity"/>
      <command_interface name="position"/>
      <command_interface name="kp"/>
      <command_interface name="kd"/>
      <state_interface initial_value="-0.2" name="position"/>
      <state_interface name="velocity"/>
      <state_interface initial_value="0.0" name="effort"/>
    </joint>
    <joint name="FL_thigh_joint">
      <command_interface name="effort"/>
      <command_interface name="velocity"/>
      <command_interface name="position"/>
      <command_interface name="kp"/>
      <command_interface name="kd"/>
      <state_interface initial_value="-0.2" name="position"/>
      <state_interface name="velocity"/>
      <state_interface initial_value="0.0" name="effort"/>
    </joint>
    <joint name="FL_calf_joint">
      <command_interface name="effort"/>
      <command_interface name="velocity"/>
      <command_interface name="position"/>
      <command_interface name="kp"/>
      <command_interface name="kd"/>
      <state_interface initial_value="-0.2" name="position"/>
      <state_interface name="velocity"/>
      <state_interface initial_value="0.0" name="effort"/>
    </joint>
    <joint name="FR_hip_joint">
      <command_interface name="effort"/>
      <command_interface name="velocity"/>
      <command_interface name="position"/>
      <command_interface name="kp"/>
      <command_interface name="kd"/>
      <state_interface initial_value="-0.2" name="position"/>
      <state_interface name="velocity"/>
      <state_interface initial_value="0.0" name="effort"/>
    </joint>
    <joint name="FR_thigh_joint">
      <command_interface name="effort"/>
      <command_interface name="velocity"/>
      <command_interface name="position"/>
      <command_interface name="kp"/>
      <command_interface name="kd"/>
      <state_interface initial_value="-0.2" name="position"/>
      <state_interface name="velocity"/>
      <state_interface initial_value="0.0" name="effort"/>
    </joint>
    <joint name="FR_calf_joint">
      <command_interface name="effort"/>
      <command_interface name="velocity"/>
      <command_interface name="position"/>
      <command_interface name="kp"/>
      <command_interface name="kd"/>
      <state_interface initial_value="-0.2" name="position"/>
      <state_interface name="velocity"/>
      <state_interface initial_value="0.0" name="effort"/>
    </joint>
    <joint name="RL_hip_joint">
      <command_interface name="effort"/>
      <command_interface name="velocity"/>
      <command_interface name="position"/>
      <command_interface name="kp"/>
      <command_interface name="kd"/>
      <state_interface initial_value="-0.2" name="position"/>
      <state_interface name="velocity"/>
      <state_interface initial_value="0.0" name="effort"/>
    </joint>
    <joint name="RL_thigh_joint">
      <command_interface name="effort"/>
      <command_interface name="velocity"/>
      <command_interface name="position"/>
      <command_interface name="kp"/>
      <command_interface name="kd"/>
      <state_interface initial_value="-0.2" name="position"/>
      <state_interface name="velocity"/>
      <state_interface initial_value="0.0" name="effort"/>
    </joint>
    <joint name="RL_calf_joint">
      <command_interface name="effort"/>
      <command_interface name="velocity"/>
      <command_interface name="position"/>
      <command_interface name="kp"/>
      <command_interface name="kd"/>
      <state_interface initial_value="-0.2" name="position"/>
      <state_interface name="velocity"/>
      <state_interface initial_value="0.0" name="effort"/>
    </joint>
    <joint name="RR_hip_joint">
      <command_interface name="effort"/>
      <command_interface name="velocity"/>
      <command_interface name="position"/>
      <command_interface name="kp"/>
      <command_interface name="kd"/>
      <state_interface initial_value="-0.2" name="position"/>
      <state_interface name="velocity"/>
      <state_interface initial_value="0.0" name="effort"/>
    </joint>
    <joint name="RR_thigh_joint">
      <command_interface name="effort"/>
      <command_interface name="velocity"/>
      <command_interface name="position"/>
      <command_interface name="kp"/>
      <command_interface name="kd"/>
      <state_interface initial_value="-0.2" name="position"/>
      <state_interface name="velocity"/>
      <state_interface initial_value="0.0" name="effort"/>
    </joint>
    <joint name="RR_calf_joint">
      <command_interface name="effort"/>
      <command_interface name="velocity"/>
      <command_interface name="position"/>
      <command_interface name="kp"/>
      <command_interface name="kd"/>
      <state_interface initial_value="-0.2" name="position"/>
      <state_interface name="velocity"/>
      <state_interface initial_value="0.0" name="effort"/>
    </joint>
    <sensor name="imu_sensor">
      <state_interface name="orientation.x"/>
      <state_interface name="orientation.y"/>
      <state_interface name="orientation.z"/>
      <state_interface name="orientation.w"/>
      <state_interface name="angular_velocity.x"/>
      <state_interface name="angular_velocity.y"/>
      <state_interface name="angular_velocity.z"/>
      <state_interface name="linear_acceleration.x"/>
      <state_interface name="linear_acceleration.y"/>
      <state_interface name="linear_acceleration.z"/>
    </sensor>
    <sensor name="fl_ft_sensor">
      <state_interface name="force.x"/>
      <state_interface name="force.y"/>
      <state_interface name="force.z"/>
      <state_interface name="torque.x"/>
      <state_interface name="torque.y"/>
      <state_interface name="torque.z"/>
      <param name="frame_id">FL_foot</param>
      <param name="fx_range">100</param>
      <param name="fy_range">100</param>
      <param name="fz_range">100</param>
      <param name="tx_range">15</param>
      <param name="ty_range">15</param>
      <param name="tz_range">15</param>
    </sensor>
    <sensor name="fr_ft_sensor">
      <state_interface name="force.x"/>
      <state_interface name="force.y"/>
      <state_interface name="force.z"/>
      <state_interface name="torque.x"/>
      <state_interface name="torque.y"/>
      <state_interface name="torque.z"/>
      <param name="frame_id">FR_foot</param>
      <param name="fx_range">100</param>
      <param name="fy_range">100</param>
      <param name="fz_range">100</param>
      <param name="tx_range">15</param>
      <param name="ty_range">15</param>
      <param name="tz_range">15</param>
    </sensor>
    <sensor name="rl_ft_sensor">
      <state_interface name="force.x"/>
      <state_interface name="force.y"/>
      <state_interface name="force.z"/>
      <state_interface name="torque.x"/>
      <state_interface name="torque.y"/>
      <state_interface name="torque.z"/>
      <param name="frame_id">RL_foot</param>
      <param name="fx_range">100</param>
      <param name="fy_range">100</param>
      <param name="fz_range">100</param>
      <param name="tx_range">15</param>
      <param name="ty_range">15</param>
      <param name="tz_range">15</param>
    </sensor>
    <sensor name="rr_ft_sensor">
      <state_interface name="force.x"/>
      <state_interface name="force.y"/>
      <state_interface name="force.z"/>
      <state_interface name="torque.x"/>
      <state_interface name="torque.y"/>
      <state_interface name="torque.z"/>
      <param name="frame_id">RR_foot</param>
      <param name="fx_range">100</param>
      <param name="fy_range">100</param>
      <param name="fz_range">100</param>
      <param name="tx_range">15</param>
      <param name="ty_range">15</param>
      <param name="tz_range">15</param>
    </sensor>
  </ros2_control>
  <!-- Show the trajectory of trunk center. -->
  <gazebo>
    <plugin filename="libgazebo_ros_p3d.so" name="libgazebo_ros_p3d">
      <ros>
        <namespace>p3d</namespace>
        <remapping>odom:=odom</remapping>
      </ros>
      <frame_name>world</frame_name>
      <body_name>base</body_name>
      <update_rate>1000.0</update_rate>
      <gaussian_noise>0.0001</gaussian_noise>
    </plugin>
  </gazebo>
  <gazebo reference="FL_foot_fixed">
    <provideFeedback>true</provideFeedback>
    <disableFixedJointLumping>true</disableFixedJointLumping>
    <gravity>true</gravity>
    <sensor name="fl_ft_sensor" type="force_torque">
      <always_on>true</always_on>
      <visualize>true</visualize>
    </sensor>
  </gazebo>
  <gazebo reference="FR_foot_fixed">
    <provideFeedback>true</provideFeedback>
    <disableFixedJointLumping>true</disableFixedJointLumping>
    <gravity>true</gravity>
    <sensor name="fr_ft_sensor" type="force_torque">
      <always_on>true</always_on>
      <visualize>true</visualize>
    </sensor>
  </gazebo>
  <gazebo reference="RL_foot_fixed">
    <provideFeedback>true</provideFeedback>
    <disableFixedJointLumping>true</disableFixedJointLumping>
    <gravity>true</gravity>
    <sensor name="rl_ft_sensor" type="force_torque">
      <always_on>true</always_on>
      <visualize>true</visualize>
    </sensor>
  </gazebo>
  <gazebo reference="RR_foot_fixed">
    <provideFeedback>true</provideFeedback>
    <disableFixedJointLumping>true</disableFixedJointLumping>
    <gravity>true</gravity>
    <sensor name="rr_ft_sensor" type="force_torque">
      <always_on>true</always_on>
      <visualize>true</visualize>
    </sensor>
  </gazebo>
  <gazebo reference="imu_link">
    <gravity>true</gravity>
    <sensor name="imu_sensor" type="imu">
      <always_on>true</always_on>
      <update_rate>1000</update_rate>
      <visualize>true</visualize>
      <topic>__default_topic__</topic>
      <plugin filename="libgazebo_ros_imu_sensor.so" name="imu_plugin">
        <topicName>trunk_imu</topicName>
        <bodyName>imu_link</bodyName>
        <updateRateHZ>1000.0</updateRateHZ>
        <gaussianNoise>0.0</gaussianNoise>
        <xyzOffset>0 0 0</xyzOffset>
        <rpyOffset>0 0 0</rpyOffset>
        <frameName>imu_link</frameName>
        <initial_orientation_as_reference>false</initial_orientation_as_reference>
      </plugin>
      <pose>0 0 0 0 0 0</pose>
    </sensor>
  </gazebo>
  <gazebo reference="camera_link">
    <sensor name="depth_camera" type="depth">
      <always_on>true</always_on>
      <visualize>true</visualize>
      <update_rate>20.0</update_rate>
      <camera>
        <horizontal_fov>1.0471975511965976</horizontal_fov>
        <image>
          <format>R8G8B8</format>
          <width>640</width>
          <height>480</height>
        </image>
        <clip>
          <near>0.05</near>
          <far>8.0</far>
        </clip>
      </camera>
      <plugin filename="libgazebo_ros_camera.so" name="depth_camera_controller">
        <baseline>0.2</baseline>
        <alwaysOn>true</alwaysOn>
        <updateRate>10.0</updateRate>
        <cameraName>camera</cameraName>
        <imageTopicName>/camera/color/image_raw</imageTopicName>
        <cameraInfoTopicName>/camera/color/camera_info</cameraInfoTopicName>
        <depthImageTopicName>/camera/depth/image_raw</depthImageTopicName>
        <depthImageInfoTopicName>/camera/depth/camera_info</depthImageInfoTopicName>
        <pointCloudTopicName>/camera/depth/points</pointCloudTopicName>
        <frame_name>camera_link_fake</frame_name>
        <pointCloudCutoff>0.5</pointCloudCutoff>
        <pointCloudCutoffMax>3.0</pointCloudCutoffMax>
        <distortionK1>0.00000001</distortionK1>
        <distortionK2>0.00000001</distortionK2>
        <distortionK3>0.00000001</distortionK3>
        <distortionT1>0.00000001</distortionT1>
        <distortionT2>0.00000001</distortionT2>
        <CxPrime>0</CxPrime>
        <Cx>0</Cx>
        <Cy>0</Cy>
        <focalLength>0</focalLength>
        <hackBaseline>0</hackBaseline>
      </plugin>
    </sensor>
  </gazebo>
  <!-- Gazebo's ros2_control plugin -->
  <gazebo>
    <plugin filename="libgazebo_ros2_control.so" name="gazebo_ros2_control">
      <robot_sim_type>gazebo_ros2_control/GazeboSystem</robot_sim_type>
      <parameters>/home/dyyt/adog_ws/install/unitree_go2_description/share/unitree_go2_description/config/robot_control_gazebo.yaml</parameters>
    </plugin>
    <selfCollide>true</selfCollide>
  </gazebo>
  <gazebo reference="base">
    <turnGravityOff>false</turnGravityOff>
  </gazebo>
  <gazebo reference="trunk">
    <mu1>0.2</mu1>
    <mu2>0.2</mu2>
    <kp value="1000000.0"/>
    <kd value="1.0"/>
  </gazebo>
  <gazebo reference="stick_link">
    <mu1>0.2</mu1>
    <mu2>0.2</mu2>
  </gazebo>
  <gazebo reference="imu_link">
    <mu1>0.2</mu1>
    <mu2>0.2</mu2>
  </gazebo>
  <!-- FL leg -->
  <gazebo reference="FL_hip">
    <mu1>0.2</mu1>
    <mu2>0.2</mu2>
  </gazebo>
  <gazebo reference="FL_thigh">
    <mu1>0.2</mu1>
    <mu2>0.2</mu2>
    <self_collide>1</self_collide>
    <kp value="1000000.0"/>
    <kd value="1.0"/>
  </gazebo>
  <gazebo reference="FL_calf">
    <mu1>0.2</mu1>
    <mu2>0.2</mu2>
    <self_collide>1</self_collide>
  </gazebo>
  <gazebo reference="FL_foot">
    <mu1>0.6</mu1>
    <mu2>0.6</mu2>
    <self_collide>1</self_collide>
    <kp value="1000000.0"/>
    <kd value="1.0"/>
  </gazebo>
  <!-- FR leg -->
  <gazebo reference="FR_hip">
    <mu1>0.2</mu1>
    <mu2>0.2</mu2>
  </gazebo>
  <gazebo reference="FR_thigh">
    <mu1>0.2</mu1>
    <mu2>0.2</mu2>
    <self_collide>1</self_collide>
    <kp value="1000000.0"/>
    <kd value="1.0"/>
  </gazebo>
  <gazebo reference="FR_calf">
    <mu1>0.2</mu1>
    <mu2>0.2</mu2>
    <self_collide>1</self_collide>
  </gazebo>
  <gazebo reference="FR_foot">
    <mu1>0.6</mu1>
    <mu2>0.6</mu2>
    <self_collide>1</self_collide>
    <kp value="1000000.0"/>
    <kd value="1.0"/>
  </gazebo>
  <!-- RL leg -->
  <gazebo reference="RL_hip">
    <mu1>0.2</mu1>
    <mu2>0.2</mu2>
  </gazebo>
  <gazebo reference="RL_thigh">
    <mu1>0.2</mu1>
    <mu2>0.2</mu2>
    <self_collide>1</self_collide>
    <kp value="1000000.0"/>
    <kd value="1.0"/>
  </gazebo>
  <gazebo reference="RL_calf">
    <mu1>0.2</mu1>
    <mu2>0.2</mu2>
    <self_collide>1</self_collide>
  </gazebo>
  <gazebo reference="RL_foot">
    <mu1>0.6</mu1>
    <mu2>0.6</mu2>
    <self_collide>1</self_collide>
    <kp value="1000000.0"/>
    <kd value="1.0"/>
  </gazebo>
  <!-- RR leg -->
  <gazebo reference="RR_hip">
    <mu1>0.2</mu1>
    <mu2>0.2</mu2>
  </gazebo>
  <gazebo reference="RR_thigh">
    <mu1>0.2</mu1>
    <mu2>0.2</mu2>
    <self_collide>1</self_collide>
    <kp value="1000000.0"/>
    <kd value="1.0"/>
  </gazebo>
  <gazebo reference="RR_calf">
    <mu1>0.2</mu1>
    <mu2>0.2</mu2>
    <self_collide>1</self_collide>
  </gazebo>
  <gazebo reference="RR_foot">
    <mu1>0.6</mu1>
    <mu2>0.6</mu2>
    <self_collide>1</self_collide>
    <kp value="1000000.0"/>
    <kd value="1.0"/>
  </gazebo>
  <!-- <xacro:stairs stairs="15" xpos="0" ypos="0" zpos="0" /> -->
  <!-- Rotor related joint and link is only for demonstrate location. -->
  <!-- Actually, the rotor will rotate and the joint is not fixed. Reduction ratio should be considered. -->
  <!-- Debug mode will hung up the robot, use "true" or "false" to switch it. -->
  <link name="base"> </link>
  <!-- <joint name="base_joint" type="fixed">
		<parent link="base_footprint" />
		<child link="base" />
		<origin xyz="0 0 0.35"/>
	</joint> -->
  <joint name="floating_base" type="fixed">
    <!-- <origin rpy="0 0 0" xyz="0 0 0.245"/> -->
    <origin rpy="0 0 0" xyz="0 0 0"/>
    <parent link="base"/>
    <child link="trunk"/>
  </joint>
  <joint name="rslidar_base_mount_joint" type="fixed">
    <origin rpy="0 0 0" xyz="0.2 0 0.08"/>
    <parent link="trunk"/>
    <child link="rslidar_base_link"/>
  </joint>
  <link name="rslidar_base_link">
    <inertial>
      <mass value="0.83"/>
      <origin xyz="0 0 0.03585"/>
      <inertia ixx="0.000908059425" ixy="0" ixz="0" iyy="0.000908059425" iyz="0" izz="0.0011049624"/>
    </inertial>
    <visual>
      <geometry>
        <mesh filename="package://velodyne_description/meshes/VLP16_base_1.dae"/>
      </geometry>
    </visual>
    <visual>
      <geometry>
        <mesh filename="package://velodyne_description/meshes/VLP16_base_2.dae"/>
      </geometry>
    </visual>
    <collision>
      <origin rpy="0 0 0" xyz="0 0 0.03585"/>
      <geometry>
        <cylinder length="0.0717" radius="0.0516"/>
      </geometry>
    </collision>
  </link>
  <joint name="rslidar_base_scan_joint" type="fixed">
    <origin rpy="0 0 0" xyz="0 0 0.0377"/>
    <parent link="rslidar_base_link"/>
    <child link="rslidar"/>
  </joint>
  <link name="rslidar">
    <inertial>
      <mass value="0.01"/>
      <origin xyz="0 0 0"/>
      <inertia ixx="1e-7" ixy="0" ixz="0" iyy="1e-7" iyz="0" izz="1e-7"/>
    </inertial>
    <visual>
      <origin xyz="0 0 -0.0377"/>
      <geometry>
        <mesh filename="package://velodyne_description/meshes/VLP16_scan.dae"/>
      </geometry>
    </visual>
    <collision>
      <geometry>
        <sphere radius="0"/>
      </geometry>
    </collision>
  </link>
  <!-- Gazebo requires the velodyne_gazebo_plugins package -->
  <gazebo reference="rslidar">
    <sensor name="rslidar-VLP16" type="gpu_ray">
      <pose>0 0 0 0 0 0</pose>
      <visualize>false</visualize>
      <update_rate>10</update_rate>
      <ray>
        <scan>
          <horizontal>
            <samples>440</samples>
            <resolution>1</resolution>
            <min_angle>-3.141592653589793</min_angle>
            <max_angle>3.141592653589793</max_angle>
          </horizontal>
          <vertical>
            <samples>16</samples>
            <resolution>1</resolution>
            <min_angle>-0.2617993877991494</min_angle>
            <max_angle> 0.2617993877991494</max_angle>
          </vertical>
        </scan>
        <range>
          <min>0.3</min>
          <max>131.0</max>
          <resolution>0.001</resolution>
        </range>
        <noise>
          <type>gaussian</type>
          <mean>0.0</mean>
          <stddev>0.0</stddev>
        </noise>
      </ray>
      <plugin filename="libgazebo_ros_velodyne_laser.so" name="gazebo_ros_laser_controller">
        <ros>
          <namespace>/rslidar</namespace>
          <remapping>~/out:=/rslidar_points</remapping>
        </ros>
        <tf_prefix></tf_prefix>
        <frame_name>rslidar</frame_name>
        <organize_cloud>True</organize_cloud>
        <min_range>0.9</min_range>
        <max_range>130.0</max_range>
        <gaussian_noise>0.008</gaussian_noise>
      </plugin>
    </sensor>
  </gazebo>
  <link name="camera_link">

    </link>
  <joint name="camera_joint" type="fixed">
    <!-- <origin rpy="0 0 0" xyz="0 0 0.245"/> -->
    <origin rpy="0 0.0 0.0" xyz="0 0 0.45"/>
    <parent link="trunk"/>
    <child link="camera_link"/>
  </joint>
  <link name="camera_link_fake"/>
  <joint name="camera_joint_fake" type="fixed">
    <origin rpy="-1.57 0 -1.57 " xyz="0 0 0"/>
    <parent link="camera_link"/>
    <child link="camera_link_fake"/>
  </joint>
  <!-- <xacro:include filename="$(find realsense_ros2_gazebo)/xacro/depthcam.xacro"/>

<xacro:realsense_R200 sensor_name="camera" parent_link="trunk" rate="30.0">
  <origin rpy="0 0 0" xyz="0 0 0.5"/>
</xacro:realsense_R200>
  -->
  <link name="trunk">
    <visual>
      <origin rpy="0 0 0" xyz="0 0 0"/>
      <geometry>
        <mesh filename="file:///home/dyyt/adog_ws/install/unitree_go2_description/share/unitree_go2_description/meshes/trunk.dae" scale="1 1 1"/>
      </geometry>
      <material name="orange"/>
    </visual>
    <collision>
      <origin rpy="0 0 0" xyz="0 0 0"/>
      <!-- <geometry>
                <mesh filename="file://$(find unitree_go2_description)/meshes/trunk.dae" scale="1 1 1"/>
            </geometry> -->
      <geometry>
        <box size="0.3762 0.0935 0.114"/>
      </geometry>
    </collision>
    <inertial>
      <origin rpy="0 0 0" xyz="0.021112 0.0 -0.005366"/>
      <mass value="6.921"/>
      <inertia ixx="0.02448" ixy="0.00012166" ixz="0.0014849" iyy="0.098077" iyz="-3.12e-05" izz="0.107"/>
    </inertial>
  </link>
  <joint name="imu_joint" type="fixed">
    <parent link="trunk"/>
    <child link="imu_link"/>
    <origin rpy="0 0 0" xyz="0 0 0"/>
  </joint>
  <link name="imu_link">
    <inertial>
      <mass value="0.001"/>
      <origin rpy="0 0 0" xyz="0 0 0"/>
      <inertia ixx="0.0001" ixy="0" ixz="0" iyy="0.0001" iyz="0" izz="0.0001"/>
    </inertial>
    <visual>
      <origin rpy="0 0 0" xyz="0 0 0"/>
      <geometry>
        <box size="0.001 0.001 0.001"/>
      </geometry>
      <!-- <material name="red"/> -->
    </visual>
    <collision>
      <origin rpy="0 0 0" xyz="0 0 0"/>
      <geometry>
        <box size=".001 .001 .001"/>
      </geometry>
    </collision>
  </link>
  <joint name="FR_hip_joint" type="revolute">
    <origin rpy="0 0 0" xyz="0.1934 -0.0465 0"/>
    <parent link="trunk"/>
    <child link="FR_hip"/>
    <axis xyz="1 0 0"/>
    <dynamics damping="0.0" friction="0.0"/>
    <limit effort="23.7" lower="-1.0472" upper="1.0472" velocity="30.1"/>
  </joint>
  <link name="FR_hip">
    <visual>
      <origin rpy="3.141592653589793 0 0" xyz="0 0 0"/>
      <geometry>
        <mesh filename="file:///home/dyyt/adog_ws/install/unitree_go2_description/share/unitree_go2_description/meshes/hip.dae" scale="1 1 1"/>
      </geometry>
    </visual>
    <collision>
      <origin rpy="1.5707963267948966 0 0" xyz="0 -0.0955 0"/>
      <geometry>
        <cylinder length="0.04" radius="0.046"/>
      </geometry>
    </collision>
    <inertial>
      <origin rpy="0 0 0" xyz="-0.0054 -0.00194 -0.000105"/>
      <mass value="0.678"/>
      <inertia ixx="0.00048" ixy="3.01e-06" ixz="1.11e-06" iyy="0.000884" iyz="1.42e-06" izz="0.000596"/>
    </inertial>
  </link>
  <joint name="FR_thigh_joint" type="revolute">
    <origin rpy="0 0 0" xyz="0 -0.0955 0"/>
    <parent link="FR_hip"/>
    <child link="FR_thigh"/>
    <axis xyz="0 1 0"/>
    <dynamics damping="0.0" friction="0.0"/>
    <limit effort="23.7" lower="-1.5708" upper="3.4907" velocity="30.1"/>
  </joint>
  <link name="FR_thigh">
    <visual>
      <origin rpy="0 0 0" xyz="0 0 0"/>
      <geometry>
        <mesh filename="file:///home/dyyt/adog_ws/install/unitree_go2_description/share/unitree_go2_description/meshes/thigh_mirror.dae" scale="1 1 1"/>
      </geometry>
    </visual>
    <collision>
      <origin rpy="0 1.5707963267948966 0" xyz="0 0 -0.1065"/>
      <geometry>
        <box size="0.213 0.0245 0.034"/>
      </geometry>
    </collision>
    <inertial>
      <origin rpy="0 0 0" xyz="-0.00374 0.0223 -0.0327"/>
      <mass value="1.152"/>
      <inertia ixx="0.00584" ixy="-8.72e-05" ixz="-0.000289" iyy="0.0058" iyz="-0.000808" izz="0.00103"/>
    </inertial>
  </link>
  <joint name="FR_calf_joint" type="revolute">
    <origin rpy="0 0 0" xyz="0 0 -0.213"/>
    <parent link="FR_thigh"/>
    <child link="FR_calf"/>
    <axis xyz="0 1 0"/>
    <dynamics damping="0.0" friction="0.0"/>
    <limit effort="35.55" lower="-2.7227" position="-0.5" upper="-0.83776" velocity="20.06"/>
  </joint>
  <link name="FR_calf">
    <visual>
      <origin rpy="0 0 0" xyz="0 0 0"/>
      <geometry>
        <mesh filename="file:///home/dyyt/adog_ws/install/unitree_go2_description/share/unitree_go2_description/meshes/calf.dae" scale="1 1 1"/>
      </geometry>
    </visual>
    <collision>
      <origin rpy="0 1.5707963267948966 0" xyz="0 0 -0.1065"/>
      <geometry>
        <box size="0.213 0.016 0.016"/>
      </geometry>
    </collision>
    <inertial>
      <origin rpy="0 0 0" xyz="0.00548 -0.000975 -0.115"/>
      <mass value="0.154"/>
      <inertia ixx="0.00108" ixy="3.4e-07" ixz="1.72e-05" iyy="0.0011" iyz="8.28e-06" izz="3.29e-05"/>
    </inertial>
  </link>
  <joint name="FR_foot_fixed" type="fixed">
    0
            
    <origin rpy="0 0 0" xyz="0 0 -0.213"/>
    <parent link="FR_calf"/>
    <child link="FR_foot"/>
  </joint>
  <link name="FR_foot">
    <visual>
      <origin rpy="0 0 0" xyz="0 0 0"/>
      <geometry>
        <sphere radius="0.01"/>
      </geometry>
    </visual>
    <collision>
      <origin rpy="0 0 0" xyz="0 0 0"/>
      <geometry>
        <sphere radius="0.02"/>
      </geometry>
    </collision>
    <inertial>
      <mass value="0.06"/>
      <inertia ixx="9.600000000000001e-06" ixy="0.0" ixz="0.0" iyy="9.600000000000001e-06" iyz="0.0" izz="9.600000000000001e-06"/>
    </inertial>
  </link>
  <!-- <xacro:unitree_go2_description name="${name}"/> -->
  <joint name="FL_hip_joint" type="revolute">
    <origin rpy="0 0 0" xyz="0.1934 0.0465 0"/>
    <parent link="trunk"/>
    <child link="FL_hip"/>
    <axis xyz="1 0 0"/>
    <dynamics damping="0.0" friction="0.0"/>
    <limit effort="23.7" lower="-1.0472" upper="1.0472" velocity="30.1"/>
  </joint>
  <link name="FL_hip">
    <visual>
      <origin rpy="0 0 0" xyz="0 0 0"/>
      <geometry>
        <mesh filename="file:///home/dyyt/adog_ws/install/unitree_go2_description/share/unitree_go2_description/meshes/hip.dae" scale="1 1 1"/>
      </geometry>
    </visual>
    <collision>
      <origin rpy="1.5707963267948966 0 0" xyz="0 0.0955 0"/>
      <geometry>
        <cylinder length="0.04" radius="0.046"/>
      </geometry>
    </collision>
    <inertial>
      <origin rpy="0 0 0" xyz="-0.0054 0.00194 -0.000105"/>
      <mass value="0.678"/>
      <inertia ixx="0.00048" ixy="-3.01e-06" ixz="1.11e-06" iyy="0.000884" iyz="-1.42e-06" izz="0.000596"/>
    </inertial>
  </link>
  <joint name="FL_thigh_joint" type="revolute">
    <origin rpy="0 0 0" xyz="0 0.0955 0"/>
    <parent link="FL_hip"/>
    <child link="FL_thigh"/>
    <axis xyz="0 1 0"/>
    <dynamics damping="0.0" friction="0.0"/>
    <limit effort="23.7" lower="-1.5708" upper="3.4907" velocity="30.1"/>
  </joint>
  <link name="FL_thigh">
    <visual>
      <origin rpy="0 0 0" xyz="0 0 0"/>
      <geometry>
        <mesh filename="file:///home/dyyt/adog_ws/install/unitree_go2_description/share/unitree_go2_description/meshes/thigh.dae" scale="1 1 1"/>
      </geometry>
    </visual>
    <collision>
      <origin rpy="0 1.5707963267948966 0" xyz="0 0 -0.1065"/>
      <geometry>
        <box size="0.213 0.0245 0.034"/>
      </geometry>
    </collision>
    <inertial>
      <origin rpy="0 0 0" xyz="-0.00374 -0.0223 -0.0327"/>
      <mass value="1.152"/>
      <inertia ixx="0.00584" ixy="8.72e-05" ixz="-0.000289" iyy="0.0058" iyz="0.000808" izz="0.00103"/>
    </inertial>
  </link>
  <joint name="FL_calf_joint" type="revolute">
    <origin rpy="0 0 0" xyz="0 0 -0.213"/>
    <parent link="FL_thigh"/>
    <child link="FL_calf"/>
    <axis xyz="0 1 0"/>
    <dynamics damping="0.0" friction="0.0"/>
    <limit effort="35.55" lower="-2.7227" position="-0.5" upper="-0.83776" velocity="20.06"/>
  </joint>
  <link name="FL_calf">
    <visual>
      <origin rpy="0 0 0" xyz="0 0 0"/>
      <geometry>
        <mesh filename="file:///home/dyyt/adog_ws/install/unitree_go2_description/share/unitree_go2_description/meshes/calf.dae" scale="1 1 1"/>
      </geometry>
    </visual>
    <collision>
      <origin rpy="0 1.5707963267948966 0" xyz="0 0 -0.1065"/>
      <geometry>
        <box size="0.213 0.016 0.016"/>
      </geometry>
    </collision>
    <inertial>
      <origin rpy="0 0 0" xyz="0.00548 -0.000975 -0.115"/>
      <mass value="0.154"/>
      <inertia ixx="0.00108" ixy="3.4e-07" ixz="1.72e-05" iyy="0.0011" iyz="8.28e-06" izz="3.29e-05"/>
    </inertial>
  </link>
  <joint name="FL_foot_fixed" type="fixed">
    0
            
    <origin rpy="0 0 0" xyz="0 0 -0.213"/>
    <parent link="FL_calf"/>
    <child link="FL_foot"/>
  </joint>
  <link name="FL_foot">
    <visual>
      <origin rpy="0 0 0" xyz="0 0 0"/>
      <geometry>
        <sphere radius="0.01"/>
      </geometry>
    </visual>
    <collision>
      <origin rpy="0 0 0" xyz="0 0 0"/>
      <geometry>
        <sphere radius="0.02"/>
      </geometry>
    </collision>
    <inertial>
      <mass value="0.06"/>
      <inertia ixx="9.600000000000001e-06" ixy="0.0" ixz="0.0" iyy="9.600000000000001e-06" iyz="0.0" izz="9.600000000000001e-06"/>
    </inertial>
  </link>
  <!-- <xacro:unitree_go2_description name="${name}"/> -->
  <joint name="RR_hip_joint" type="revolute">
    <origin rpy="0 0 0" xyz="-0.1934 -0.0465 0"/>
    <parent link="trunk"/>
    <child link="RR_hip"/>
    <axis xyz="1 0 0"/>
    <dynamics damping="0.0" friction="0.0"/>
    <limit effort="23.7" lower="-1.0472" upper="1.0472" velocity="30.1"/>
  </joint>
  <link name="RR_hip">
    <visual>
      <origin rpy="3.141592653589793 3.141592653589793 0" xyz="0 0 0"/>
      <geometry>
        <mesh filename="file:///home/dyyt/adog_ws/install/unitree_go2_description/share/unitree_go2_description/meshes/hip.dae" scale="1 1 1"/>
      </geometry>
    </visual>
    <collision>
      <origin rpy="1.5707963267948966 0 0" xyz="0 -0.0955 0"/>
      <geometry>
        <cylinder length="0.04" radius="0.046"/>
      </geometry>
    </collision>
    <inertial>
      <origin rpy="0 0 0" xyz="0.0054 -0.00194 -0.000105"/>
      <mass value="0.678"/>
      <inertia ixx="0.00048" ixy="-3.01e-06" ixz="-1.11e-06" iyy="0.000884" iyz="1.42e-06" izz="0.000596"/>
    </inertial>
  </link>
  <joint name="RR_thigh_joint" type="revolute">
    <origin rpy="0 0 0" xyz="0 -0.0955 0"/>
    <parent link="RR_hip"/>
    <child link="RR_thigh"/>
    <axis xyz="0 1 0"/>
    <dynamics damping="0.0" friction="0.0"/>
    <limit effort="23.7" lower="-1.5708" upper="3.4907" velocity="30.1"/>
  </joint>
  <link name="RR_thigh">
    <visual>
      <origin rpy="0 0 0" xyz="0 0 0"/>
      <geometry>
        <mesh filename="file:///home/dyyt/adog_ws/install/unitree_go2_description/share/unitree_go2_description/meshes/thigh_mirror.dae" scale="1 1 1"/>
      </geometry>
    </visual>
    <collision>
      <origin rpy="0 1.5707963267948966 0" xyz="0 0 -0.1065"/>
      <geometry>
        <box size="0.213 0.0245 0.034"/>
      </geometry>
    </collision>
    <inertial>
      <origin rpy="0 0 0" xyz="-0.00374 0.0223 -0.0327"/>
      <mass value="1.152"/>
      <inertia ixx="0.00584" ixy="-8.72e-05" ixz="-0.000289" iyy="0.0058" iyz="-0.000808" izz="0.00103"/>
    </inertial>
  </link>
  <joint name="RR_calf_joint" type="revolute">
    <origin rpy="0 0 0" xyz="0 0 -0.213"/>
    <parent link="RR_thigh"/>
    <child link="RR_calf"/>
    <axis xyz="0 1 0"/>
    <dynamics damping="0.0" friction="0.0"/>
    <limit effort="35.55" lower="-2.7227" position="-0.5" upper="-0.83776" velocity="20.06"/>
  </joint>
  <link name="RR_calf">
    <visual>
      <origin rpy="0 0 0" xyz="0 0 0"/>
      <geometry>
        <mesh filename="file:///home/dyyt/adog_ws/install/unitree_go2_description/share/unitree_go2_description/meshes/calf.dae" scale="1 1 1"/>
      </geometry>
    </visual>
    <collision>
      <origin rpy="0 1.5707963267948966 0" xyz="0 0 -0.1065"/>
      <geometry>
        <box size="0.213 0.016 0.016"/>
      </geometry>
    </collision>
    <inertial>
      <origin rpy="0 0 0" xyz="0.00548 -0.000975 -0.115"/>
      <mass value="0.154"/>
      <inertia ixx="0.00108" ixy="3.4e-07" ixz="1.72e-05" iyy="0.0011" iyz="8.28e-06" izz="3.29e-05"/>
    </inertial>
  </link>
  <joint name="RR_foot_fixed" type="fixed">
    0
            
    <origin rpy="0 0 0" xyz="0 0 -0.213"/>
    <parent link="RR_calf"/>
    <child link="RR_foot"/>
  </joint>
  <link name="RR_foot">
    <visual>
      <origin rpy="0 0 0" xyz="0 0 0"/>
      <geometry>
        <sphere radius="0.01"/>
      </geometry>
    </visual>
    <collision>
      <origin rpy="0 0 0" xyz="0 0 0"/>
      <geometry>
        <sphere radius="0.02"/>
      </geometry>
    </collision>
    <inertial>
      <mass value="0.06"/>
      <inertia ixx="9.600000000000001e-06" ixy="0.0" ixz="0.0" iyy="9.600000000000001e-06" iyz="0.0" izz="9.600000000000001e-06"/>
    </inertial>
  </link>
  <!-- <xacro:unitree_go2_description name="${name}"/> -->
  <joint name="RL_hip_joint" type="revolute">
    <origin rpy="0 0 0" xyz="-0.1934 0.0465 0"/>
    <parent link="trunk"/>
    <child link="RL_hip"/>
    <axis xyz="1 0 0"/>
    <dynamics damping="0.0" friction="0.0"/>
    <limit effort="23.7" lower="-1.0472" upper="1.0472" velocity="30.1"/>
  </joint>
  <link name="RL_hip">
    <visual>
      <origin rpy="0 3.141592653589793 0" xyz="0 0 0"/>
      <geometry>
        <mesh filename="file:///home/dyyt/adog_ws/install/unitree_go2_description/share/unitree_go2_description/meshes/hip.dae" scale="1 1 1"/>
      </geometry>
    </visual>
    <collision>
      <origin rpy="1.5707963267948966 0 0" xyz="0 0.0955 0"/>
      <geometry>
        <cylinder length="0.04" radius="0.046"/>
      </geometry>
    </collision>
    <inertial>
      <origin rpy="0 0 0" xyz="0.0054 0.00194 -0.000105"/>
      <mass value="0.678"/>
      <inertia ixx="0.00048" ixy="3.01e-06" ixz="-1.11e-06" iyy="0.000884" iyz="-1.42e-06" izz="0.000596"/>
    </inertial>
  </link>
  <joint name="RL_thigh_joint" type="revolute">
    <origin rpy="0 0 0" xyz="0 0.0955 0"/>
    <parent link="RL_hip"/>
    <child link="RL_thigh"/>
    <axis xyz="0 1 0"/>
    <dynamics damping="0.0" friction="0.0"/>
    <limit effort="23.7" lower="-1.5708" upper="3.4907" velocity="30.1"/>
  </joint>
  <link name="RL_thigh">
    <visual>
      <origin rpy="0 0 0" xyz="0 0 0"/>
      <geometry>
        <mesh filename="file:///home/dyyt/adog_ws/install/unitree_go2_description/share/unitree_go2_description/meshes/thigh.dae" scale="1 1 1"/>
      </geometry>
    </visual>
    <collision>
      <origin rpy="0 1.5707963267948966 0" xyz="0 0 -0.1065"/>
      <geometry>
        <box size="0.213 0.0245 0.034"/>
      </geometry>
    </collision>
    <inertial>
      <origin rpy="0 0 0" xyz="-0.00374 -0.0223 -0.0327"/>
      <mass value="1.152"/>
      <inertia ixx="0.00584" ixy="8.72e-05" ixz="-0.000289" iyy="0.0058" iyz="0.000808" izz="0.00103"/>
    </inertial>
  </link>
  <joint name="RL_calf_joint" type="revolute">
    <origin rpy="0 0 0" xyz="0 0 -0.213"/>
    <parent link="RL_thigh"/>
    <child link="RL_calf"/>
    <axis xyz="0 1 0"/>
    <dynamics damping="0.0" friction="0.0"/>
    <limit effort="35.55" lower="-2.7227" position="-0.5" upper="-0.83776" velocity="20.06"/>
  </joint>
  <link name="RL_calf">
    <visual>
      <origin rpy="0 0 0" xyz="0 0 0"/>
      <geometry>
        <mesh filename="file:///home/dyyt/adog_ws/install/unitree_go2_description/share/unitree_go2_description/meshes/calf.dae" scale="1 1 1"/>
      </geometry>
    </visual>
    <collision>
      <origin rpy="0 1.5707963267948966 0" xyz="0 0 -0.1065"/>
      <geometry>
        <box size="0.213 0.016 0.016"/>
      </geometry>
    </collision>
    <inertial>
      <origin rpy="0 0 0" xyz="0.00548 -0.000975 -0.115"/>
      <mass value="0.154"/>
      <inertia ixx="0.00108" ixy="3.4e-07" ixz="1.72e-05" iyy="0.0011" iyz="8.28e-06" izz="3.29e-05"/>
    </inertial>
  </link>
  <joint name="RL_foot_fixed" type="fixed">
    0
            
    <origin rpy="0 0 0" xyz="0 0 -0.213"/>
    <parent link="RL_calf"/>
    <child link="RL_foot"/>
  </joint>
  <link name="RL_foot">
    <visual>
      <origin rpy="0 0 0" xyz="0 0 0"/>
      <geometry>
        <sphere radius="0.01"/>
      </geometry>
    </visual>
    <collision>
      <origin rpy="0 0 0" xyz="0 0 0"/>
      <geometry>
        <sphere radius="0.02"/>
      </geometry>
    </collision>
    <inertial>
      <mass value="0.06"/>
      <inertia ixx="9.600000000000001e-06" ixy="0.0" ixz="0.0" iyy="9.600000000000001e-06" iyz="0.0" izz="9.600000000000001e-06"/>
    </inertial>
  </link>
  <!-- <xacro:unitree_go2_description name="${name}"/> -->
</robot>
